Spectrum = [3, 2, 1]
Traceback (most recent call last):
  File "../../relationaldef/main.py", line 101, in <module>
    main()
  File "../../relationaldef/main.py", line 16, in main
    is_open_rel(model,targets_rel)
  File "../../relationaldef/main.py", line 65, in is_open_rel
    for aut in automorphisms(current,base_rels):
  File "/home/pventura/relationaldef/minion.py", line 86, in __iter__
    solution = self.__parse_solution()
  File "/home/pventura/relationaldef/minion.py", line 77, in __parse_solution
    raise ValueError("Minion Error:\n%s" % str_err)
ValueError: Minion Error:
Sorry, there has been some kind of error.
This could be caused by a misformed input file, or by an internal bug.
If you can't figure out what is causing the problem, please report it at http://www.sourceforge.net/projects/minion.
Either on the bug tracker, or on the mailing list.

The generated error message was: calloc failed - Memory exhausted! Aborting.
The error was in the file /home/hudson/workspace/minion-release-linux/source/minion-1.8/minion/build_constraints/../memory_management/MemoryBlock.h on line 184
Minion exited abnormally via an exception.


 Performance counter stats for 'timeout --signal=SIGINT 45m python3 ../../relationaldef/main.py':

        417.678246      task-clock (msec)         #    0.934 CPUs utilized          
                12      context-switches          #    0.029 K/sec                  
                 2      cpu-migrations            #    0.005 K/sec                  
             6,812      page-faults               #    0.016 M/sec                  
       871,050,245      cycles                    #    2.085 GHz                    
     1,838,848,175      instructions              #    2.11  insn per cycle         
       405,275,696      branches                  #  970.306 M/sec                  
         2,764,334      branch-misses             #    0.68% of all branches        

       0.446968182 seconds time elapsed

